Traceback (most recent call last):
  File "C:\Users\Admin\anaconda3\Lib\site-packages\myst_nb\core\execute\inline.py", line 120, in code_cell_outputs
    self._client.execute_cell(
  File "C:\Users\Admin\anaconda3\Lib\site-packages\jupyter_core\utils\__init__.py", line 165, in wrapped
    return loop.run_until_complete(inner)
           ^^^^^^^^^^^^^^^^^^^^^^^^^^^^^^
  File "C:\Users\Admin\anaconda3\Lib\asyncio\base_events.py", line 653, in run_until_complete
    return future.result()
           ^^^^^^^^^^^^^^^
  File "C:\Users\Admin\anaconda3\Lib\site-packages\nbclient\client.py", line 1062, in async_execute_cell
    await self._check_raise_for_error(cell, cell_index, exec_reply)
  File "C:\Users\Admin\anaconda3\Lib\site-packages\nbclient\client.py", line 918, in _check_raise_for_error
    raise CellExecutionError.from_cell_and_msg(cell, exec_reply_content)
nbclient.exceptions.CellExecutionError: An error occurred while executing the following cell:
------------------
import yfinance as yf
ko = yf.Ticker("KO")
hist = ko.history(period="3mo")
print(hist.iloc[8]) # 2023-12-29, 58.46
price = 58.46
------------------


[1;31m---------------------------------------------------------------------------[0m
[1;31mModuleNotFoundError[0m                       Traceback (most recent call last)
Cell [1;32mIn[44], line 1[0m
[1;32m----> 1[0m [38;5;28;01mimport[39;00m [38;5;21;01myfinance[39;00m [38;5;28;01mas[39;00m [38;5;21;01myf[39;00m
[0;32m      2[0m ko [38;5;241m=[39m yf[38;5;241m.[39mTicker([38;5;124m"[39m[38;5;124mKO[39m[38;5;124m"[39m)
[0;32m      3[0m hist [38;5;241m=[39m ko[38;5;241m.[39mhistory(period[38;5;241m=[39m[38;5;124m"[39m[38;5;124m3mo[39m[38;5;124m"[39m)

[1;31mModuleNotFoundError[0m: No module named 'yfinance'

