Traceback (most recent call last):
  File "C:\Users\Admin\anaconda3\Lib\site-packages\jupyter_cache\executors\utils.py", line 58, in single_nb_execution
    executenb(
  File "C:\Users\Admin\anaconda3\Lib\site-packages\nbclient\client.py", line 1314, in execute
    return NotebookClient(nb=nb, resources=resources, km=km, **kwargs).execute()
           ^^^^^^^^^^^^^^^^^^^^^^^^^^^^^^^^^^^^^^^^^^^^^^^^^^^^^^^^^^^^^^^^^^^^^
  File "C:\Users\Admin\anaconda3\Lib\site-packages\jupyter_core\utils\__init__.py", line 165, in wrapped
    return loop.run_until_complete(inner)
           ^^^^^^^^^^^^^^^^^^^^^^^^^^^^^^
  File "C:\Users\Admin\anaconda3\Lib\asyncio\base_events.py", line 653, in run_until_complete
    return future.result()
           ^^^^^^^^^^^^^^^
  File "C:\Users\Admin\anaconda3\Lib\site-packages\nbclient\client.py", line 709, in async_execute
    await self.async_execute_cell(
  File "C:\Users\Admin\anaconda3\Lib\site-packages\nbclient\client.py", line 1062, in async_execute_cell
    await self._check_raise_for_error(cell, cell_index, exec_reply)
  File "C:\Users\Admin\anaconda3\Lib\site-packages\nbclient\client.py", line 918, in _check_raise_for_error
    raise CellExecutionError.from_cell_and_msg(cell, exec_reply_content)
nbclient.exceptions.CellExecutionError: An error occurred while executing the following cell:
------------------
from financetoolkit import Toolkit

API_KEY = "*"
companies = Toolkit(['KO'], api_key=API_KEY, start_date="2017-12-31")

# Getting the balance sheet
bs = companies.get_balance_sheet_statement()[[str(i) for i in range(2019, 2024)]]
bs.to_csv('ko_bs_2023-2019_financetoolkit.csv')

# Getting the income statement
ics = companies.get_income_statement()
ics.to_csv('ko_ics_2023-2019_financetoolkit.csv')

# Getting the cash flow statement
cfs = companies.get_cash_flow_statement()
cfs.to_csv('ko_cfs_2023-2019_financetoolkit.csv')
------------------

----- stderr -----
Obtaining balance data:   0%|                                                                    | 0/1 [00:00<?, ?it/s]
----- stderr -----
Obtaining balance data: 100%|â–ˆâ–ˆâ–ˆâ–ˆâ–ˆâ–ˆâ–ˆâ–ˆâ–ˆâ–ˆâ–ˆâ–ˆâ–ˆâ–ˆâ–ˆâ–ˆâ–ˆâ–ˆâ–ˆâ–ˆâ–ˆâ–ˆâ–ˆâ–ˆâ–ˆâ–ˆâ–ˆâ–ˆâ–ˆâ–ˆâ–ˆâ–ˆâ–ˆâ–ˆâ–ˆâ–ˆâ–ˆâ–ˆâ–ˆâ–ˆâ–ˆâ–ˆâ–ˆâ–ˆâ–ˆâ–ˆâ–ˆâ–ˆâ–ˆâ–ˆâ–ˆâ–ˆâ–ˆâ–ˆâ–ˆâ–ˆâ–ˆâ–ˆâ–ˆâ–ˆ| 1/1 [00:00<00:00,  9.88it/s]
----- stderr -----
Obtaining balance data: 100%|â–ˆâ–ˆâ–ˆâ–ˆâ–ˆâ–ˆâ–ˆâ–ˆâ–ˆâ–ˆâ–ˆâ–ˆâ–ˆâ–ˆâ–ˆâ–ˆâ–ˆâ–ˆâ–ˆâ–ˆâ–ˆâ–ˆâ–ˆâ–ˆâ–ˆâ–ˆâ–ˆâ–ˆâ–ˆâ–ˆâ–ˆâ–ˆâ–ˆâ–ˆâ–ˆâ–ˆâ–ˆâ–ˆâ–ˆâ–ˆâ–ˆâ–ˆâ–ˆâ–ˆâ–ˆâ–ˆâ–ˆâ–ˆâ–ˆâ–ˆâ–ˆâ–ˆâ–ˆâ–ˆâ–ˆâ–ˆâ–ˆâ–ˆâ–ˆâ–ˆ| 1/1 [00:00<00:00,  9.60it/s]
----- stderr -----

----- stdout -----
You have entered an invalid API key from FinancialModelingPrep. Obtain your API key for free and get 15% off the Premium plans by using the following affiliate link.
This also supports the project: https://www.jeroenbouma.com/fmp
No data found for the following tickers: KO
------------------

[1;31m---------------------------------------------------------------------------[0m
[1;31mKeyError[0m                                  Traceback (most recent call last)
Cell [1;32mIn[20], line 7[0m
[0;32m      4[0m companies [38;5;241m=[39m Toolkit([[38;5;124m'[39m[38;5;124mKO[39m[38;5;124m'[39m], api_key[38;5;241m=[39mAPI_KEY, start_date[38;5;241m=[39m[38;5;124m"[39m[38;5;124m2017-12-31[39m[38;5;124m"[39m)
[0;32m      6[0m [38;5;66;03m# Getting the balance sheet[39;00m
[1;32m----> 7[0m bs [38;5;241m=[39m companies[38;5;241m.[39mget_balance_sheet_statement()[[[38;5;28mstr[39m(i) [38;5;28;01mfor[39;00m i [38;5;129;01min[39;00m [38;5;28mrange[39m([38;5;241m2019[39m, [38;5;241m2024[39m)]]
[0;32m      8[0m bs[38;5;241m.[39mto_csv([38;5;124m'[39m[38;5;124mko_bs_2023-2019_financetoolkit.csv[39m[38;5;124m'[39m)
[0;32m     10[0m [38;5;66;03m# Getting the income statement[39;00m

File [1;32m~\anaconda3\Lib\site-packages\pandas\core\frame.py:4096[0m, in [0;36mDataFrame.__getitem__[1;34m(self, key)[0m
[0;32m   4094[0m     [38;5;28;01mif[39;00m is_iterator(key):
[0;32m   4095[0m         key [38;5;241m=[39m [38;5;28mlist[39m(key)
[1;32m-> 4096[0m     indexer [38;5;241m=[39m [38;5;28mself[39m[38;5;241m.[39mcolumns[38;5;241m.[39m_get_indexer_strict(key, [38;5;124m"[39m[38;5;124mcolumns[39m[38;5;124m"[39m)[[38;5;241m1[39m]
[0;32m   4098[0m [38;5;66;03m# take() does not accept boolean indexers[39;00m
[0;32m   4099[0m [38;5;28;01mif[39;00m [38;5;28mgetattr[39m(indexer, [38;5;124m"[39m[38;5;124mdtype[39m[38;5;124m"[39m, [38;5;28;01mNone[39;00m) [38;5;241m==[39m [38;5;28mbool[39m:

File [1;32m~\anaconda3\Lib\site-packages\pandas\core\indexes\base.py:6200[0m, in [0;36mIndex._get_indexer_strict[1;34m(self, key, axis_name)[0m
[0;32m   6197[0m [38;5;28;01melse[39;00m:
[0;32m   6198[0m     keyarr, indexer, new_indexer [38;5;241m=[39m [38;5;28mself[39m[38;5;241m.[39m_reindex_non_unique(keyarr)
[1;32m-> 6200[0m [38;5;28mself[39m[38;5;241m.[39m_raise_if_missing(keyarr, indexer, axis_name)
[0;32m   6202[0m keyarr [38;5;241m=[39m [38;5;28mself[39m[38;5;241m.[39mtake(indexer)
[0;32m   6203[0m [38;5;28;01mif[39;00m [38;5;28misinstance[39m(key, Index):
[0;32m   6204[0m     [38;5;66;03m# GH 42790 - Preserve name from an Index[39;00m

File [1;32m~\anaconda3\Lib\site-packages\pandas\core\indexes\base.py:6249[0m, in [0;36mIndex._raise_if_missing[1;34m(self, key, indexer, axis_name)[0m
[0;32m   6247[0m [38;5;28;01mif[39;00m nmissing:
[0;32m   6248[0m     [38;5;28;01mif[39;00m nmissing [38;5;241m==[39m [38;5;28mlen[39m(indexer):
[1;32m-> 6249[0m         [38;5;28;01mraise[39;00m [38;5;167;01mKeyError[39;00m([38;5;124mf[39m[38;5;124m"[39m[38;5;124mNone of [[39m[38;5;132;01m{[39;00mkey[38;5;132;01m}[39;00m[38;5;124m] are in the [[39m[38;5;132;01m{[39;00maxis_name[38;5;132;01m}[39;00m[38;5;124m][39m[38;5;124m"[39m)
[0;32m   6251[0m     not_found [38;5;241m=[39m [38;5;28mlist[39m(ensure_index(key)[missing_mask[38;5;241m.[39mnonzero()[[38;5;241m0[39m]][38;5;241m.[39munique())
[0;32m   6252[0m     [38;5;28;01mraise[39;00m [38;5;167;01mKeyError[39;00m([38;5;124mf[39m[38;5;124m"[39m[38;5;132;01m{[39;00mnot_found[38;5;132;01m}[39;00m[38;5;124m not in index[39m[38;5;124m"[39m)

[1;31mKeyError[0m: "None of [Index(['2019', '2020', '2021', '2022', '2023'], dtype='object')] are in the [columns]"

